<?xml version="1.0"?>
<robot xmlns:xacro="http://www.ros.org/wiki/xacro" name="machine_tool" >
    <xacro:include filename="$(find machine_tool_description)/urdf/xacro/common.gazebo.xacro" />

    <material name="Aquamarine1"><color rgba="0.5 1 0.85 1"/></material>
    <material name="white"><color rgba="1 1 1 1"/></material>
    <material name="MediumBlue"><color rgba="0 0 0.8 1"/></material>
    <material name="Tomato"><color rgba="1 0.4 0.36 1"/></material>
    <link name="world"/>

    <link name="base_table">
        <visual>
            <origin xyz="0 0 0" rpy="0 0 0" />
            <geometry>
                <box size="1.0 1.0 0.1" />
            </geometry>
            <material name="white"/>
        </visual>
        <collision>
            <origin xyz="0 0 0" rpy="0 0 0" />
            <geometry>
                <box size="1.0 1.0 0.1" />
            </geometry>
        </collision>
        <inertial>
            <origin xyz="0 0 0" rpy="0 0 0" />
            <mass value="100"/>
            <inertia
                ixx="8.5" ixy="0.0" ixz="0.0"
                iyy="8.5" iyz="0.0"
                izz="17"/>
        </inertial>
        <surface>
            <friction>
                <ode>
                <mu>100</mu>
                <mu2>100</mu2>
                </ode>
            </friction>
        </surface>
    </link>

    <joint name="fixed" type="fixed">
        <origin xyz="0 0 0.05" rpy="0 0 0" />
        <parent link="world"/>
        <child link="base_table"/>
    </joint>

    <link name="x_axle">
        <visual>
            <origin xyz="0 0 0" rpy="0 0 0" />
            <geometry>
                <box size="1.0 0.03 0.03" />
            </geometry>
            <material name="Aquamarine1"/>
        </visual>
        <collision>
            <origin xyz="0 0 0" rpy="0 0 0" />
            <geometry>
                <box size="1.0 0.03 0.03" />
            </geometry>
        </collision>
        <inertial>
            <origin xyz="0 0 0" rpy="0 0 0" />
            <mass value="10"/>
            <inertia
                ixx="0.02" ixy="0.0" ixz="0.0"
                iyy="0.85" iyz="0.0"
                izz="0.85"/>
        </inertial>
        <surface>
            <friction>
                <ode>
                <mu>100</mu>
                <mu2>100</mu2>
                </ode>
            </friction>
        </surface>
    </link>

    <joint name="x_joint" type="prismatic">
       <origin xyz="0 0 0.1" rpy="0 0 0"></origin>
        <parent link="base_table" />
        <child link="x_axle"/>
        <axis xyz="1 0 0" />
        <limit effort="30" velocity="100.0" lower="-0.5" upper="0.5" />
    </joint>

    <link name="y_axle">
        <visual>
            <origin xyz="0 0 0" rpy="0 0 0" />
            <geometry>
                <box size="0.03 1.0 0.03" />
            </geometry>
            <material name="MediumBlue"/>
        </visual>
        <collision>
            <origin xyz="0 0 0" rpy="0 0 0" />
            <geometry>
                <box size="0.03 1.0 0.03" />
            </geometry>
        </collision>
        <inertial>
            <origin xyz="0 0 0" rpy="0 0 0" />
            <mass value="10"/>
            <inertia
                ixx="0.85" ixy="0.0" ixz="0.0"
                iyy="0.02" iyz="0.0"
                izz="0.85"/>
        </inertial>
        <surface>
            <friction>
                <ode>
                <mu>100</mu>
                <mu2>100</mu2>
                </ode>
            </friction>
        </surface>
    </link>

    <joint name="y_joint" type="prismatic">
       <origin xyz="0 0 0" rpy="0 0 0"></origin>
        <parent link="x_axle" />
        <child link="y_axle"/>
        <axis xyz="0 1 0" />
        <limit effort="30" velocity="100.0" lower="-0.5" upper="0.5" />
    </joint>

    <link name="plate">
        <visual>
            <origin xyz="0 0 0" rpy="0 0 0" />
            <geometry>
                <box size="0.05 0.05 0.01" />
            </geometry>
            <material name="Tomato"/>
        </visual>
        <collision>
            <origin xyz="0 0 0" rpy="0 0 0" />
            <geometry>
                <box size="0.2 0.2 0.05" />
            </geometry>
        </collision>
        <inertial>
            <origin xyz="0 0 0" rpy="0 0 0" />
            <mass value="1"/>
            <inertia
                ixx="0.01" ixy="0.0" ixz="0.0"
                iyy="0.01" iyz="0.0"
                izz="0.01"/>
        </inertial>
        <surface>
            <friction>
                <ode>
                <mu>100</mu>
                <mu2>100</mu2>
                </ode>
            </friction>
        </surface>
    </link>

    <joint name="r_joint" type="revolute">
        <origin xyz="0 0 0.06" rpy="0 0 0"></origin>
        <parent link="y_axle" />
        <child link="plate"/>
        <axis xyz="0 0 1" />
        <limit effort="30" velocity="100.0" lower="-6.28" upper="6.28" />
    </joint>

    <link name="iphone">
      <visual>
        <geometry>
          <mesh filename="package://machine_tool_description/meshes/iphone/test_model.STL" scale = "0.001 0.001 0.001" />
        </geometry>
        <material name="LightGrey">
          <color rgba="0.75294 0.75294 0.75294 1" />
        </material>
      </visual>
      <collision>
        <geometry>
            <box size="0.1 0.1 0.05" />
        </geometry>
      </collision>
      <inertial>
        <mass value="0.034" />
        <origin xyz="0.0 0.0 0.0" />
        <inertia ixx = "0.0022573" ixy = "0.000000" ixz = "0.000000"
                iyx = "0.000000" iyy = "0.0038711" iyz = "0.0003245"
                izx = "0.000000" izy = "0.0003245" izz = "0.0023745" />
      </inertial>
    </link>


    <joint name="plate_joine" type="fixed">
        <origin xyz="-0.0358 0.07353 0" rpy="1.5707963 0 0"></origin>
        <parent link="plate" />
        <child link="iphone"/>
        <axis xyz="0 0 1" />
    </joint>


    <transmission name="x_joint_trans">
      <type>transmission_interface/SimpleTransmission</type>
      <joint name="x_joint">
      <hardwareInterface>hardware_interface/VelocityJointInterface</hardwareInterface>
      </joint>
      <actuator name="x_joint_motor">
      <hardwareInterface>hardware_interface/VelocityJointInterface</hardwareInterface>
        <mechanicalReduction>1</mechanicalReduction>
      </actuator>
    </transmission>

    <transmission name="y_joint_trans">
      <type>transmission_interface/SimpleTransmission</type>
      <joint name="y_joint">
      <hardwareInterface>hardware_interface/VelocityJointInterface</hardwareInterface>
      </joint>
      <actuator name="y_joint_motor">
      <hardwareInterface>hardware_interface/VelocityJointInterface</hardwareInterface>
        <mechanicalReduction>1</mechanicalReduction>
      </actuator>
    </transmission>

    <transmission name="r_joint_trans">
      <type>transmission_interface/SimpleTransmission</type>
      <joint name="r_joint">
      <hardwareInterface>hardware_interface/VelocityJointInterface</hardwareInterface>
      </joint>
      <actuator name="r_joint_motor">
      <hardwareInterface>hardware_interface/VelocityJointInterface</hardwareInterface>
        <mechanicalReduction>1</mechanicalReduction>
      </actuator>
    </transmission>
    <!-- <gazebo>
      <plugin name="p3d_base_controller" filename="libgazebo_ros_p3d.so">
        <alwaysOn>true</alwaysOn>
        <updateRate>50.0</updateRate>
        <bodyName>ee_link</bodyName>
        <topicName>wrist_pose_ground_truth</topicName>
        <gaussianNoise>0.0</gaussianNoise>
        <frameName>world</frameName>
        <xyzOffsets>0 0 0</xyzOffsets>
        <rpyOffsets>0 0 0</rpyOffsets>
      </plugin>
    </gazebo> -->

</robot>